Workbook

Sheet Summary
A1: Corporate Credit Portfolio - Summary & Watchlist
A2: All figures from SEC EDGAR XBRL filings. Covenant thresholds are stated assumptions (see Assumptions tab), not real negotiated terms.
A4: Ticker | B4: Company | C4: Period end | D4: Internal grade | E4: PD proxy band | F4: Watchlist | G4: Revenue TTM | H4: EBITDA TTM | I4: Op margin | J4: Total debt | K4: Net debt | L4: Debt/EBITDA | M4: Net debt/EBITDA | N4: EBITDA/interest | O4: FCF TTM | P4: FCF/debt | Q4: Current ratio | R4: Quick ratio | S4: Working capital | T4: Altman Z" | U4: Z" zone | V4: Debt due <1y | W4: Data coverage | X4: Covenant headroom (turns) | Y4: Covenant status
A5: W | B5: Wayfair Inc. | C5: 46203 | D5: B | E5: High | F5: High | G5: 12904000000 | H5: 492000000 | I5: 0.0166615 | J5: 2797000000 | K5: 1654000000 | L5: 5.6849593 | M5: 3.3617886 | N5: 3.3931034 | O5: 562000000 | P5: 0.20092957 | Q5: 0.74294533 | R5: 0.70590829 | S5: -583000000 | T5: -6.7025358 | U5: Distress | W5: 1 | X5: =IF(ISBLANK(L5),"n/a",Assumptions!$C$5-L5) | Y5: =IF(ISBLANK(L5),"no data",IF(L5>Assumptions!$C$5,"BREACH","Compliant"))
A6: BBWI | B6: Bath & Body Works, Inc. | C6: 46144 | D6: BB | E6: Medium | F6: Medium | G6: 7245000000 | H6: 1399000000 | I6: 0.15845411 | J6: 3613000000 | K6: 2793000000 | L6: 2.582559 | M6: 1.996426 | N6: 5.1245421 | O6: 909000000 | P6: 0.25159148 | Q6: 1.379085 | R6: 0.81118373 | S6: 522000000 | T6: 1.2008483 | U6: Grey | V6: 0.072522983 | W6: 1 | X6: =IF(ISBLANK(L6),"n/a",Assumptions!$C$5-L6) | Y6: =IF(ISBLANK(L6),"no data",IF(L6>Assumptions!$C$5,"BREACH","Compliant"))
A7: TGT | B7: TARGET CORP | C7: 46144 | D7: BBB | E7: Medium | F7: Medium | G7: 106377000000 | H7: 7940000000 | I7: 0.044934525 | J7: 15415000000 | K7: 7270000000 | L7: 1.9414358 | M7: 0.91561713 | N7: 17.762864 | O7: 3031000000 | P7: 0.19662666 | Q7: 0.93195419 | R7: 0.29653322 | S7: -1319000000 | T7: 1.3550302 | U7: Grey | V7: 0.13792152 | W7: 1 | X7: =IF(ISBLANK(L7),"n/a",Assumptions!$C$5-L7) | Y7: =IF(ISBLANK(L7),"no data",IF(L7>Assumptions!$C$5,"BREACH","Compliant"))
A8: BURL | B8: Burlington Stores, Inc. | C8: 46144 | D8: BBB | E8: Medium | F8: Clear | G8: 11901842000 | H8: 1310105000 | I8: 0.073888563 | J8: 1917363000 | K8: 1170008000 | L8: 1.4635186 | M8: 0.8930643 | N8: 18.265413 | O8: 382940000 | P8: 0.19972222 | Q8: 1.1638641 | R8: 0.49290482 | S8: 352709000 | T8: 1.8216772 | U8: Grey | V8: 0.0086429038 | W8: 1 | X8: =IF(ISBLANK(L8),"n/a",Assumptions!$C$5-L8) | Y8: =IF(ISBLANK(L8),"no data",IF(L8>Assumptions!$C$5,"BREACH","Compliant"))
A9: M | B9: Macy's, Inc. | C9: 46144 | D9: A | E9: Low | F9: Clear | G9: 21846000000 | H9: 1933000000 | I9: 0.047972169 | J9: 2432000000 | K9: 1138000000 | L9: 1.258148 | M9: 0.58872219 | N9: 20.347368 | O9: 1425000000 | P9: 0.5859375 | Q9: 1.4753958 | R9: 0.44137783 | S9: 2222000000 | T9: 3.1563457 | U9: Safe | V9: 0.013928718 | W9: 1 | X9: =IF(ISBLANK(L9),"n/a",Assumptions!$C$5-L9) | Y9: =IF(ISBLANK(L9),"no data",IF(L9>Assumptions!$C$5,"BREACH","Compliant"))
A10: DKS | B10: DICK'S SPORTING GOODS, INC. | C10: 46144 | D10: AA | E10: Low | F10: Medium | G10: 19204947000 | H10: 1725022000 | I10: 0.061465517 | J10: 1905810000 | K10: 907582000 | L10: 1.1048033 | M10: 0.52612778 | N10: 24.761674 | O10: 402619000 | P10: 0.21125873 | Q10: 1.5008652 | R10: 0.38211569 | S10: 2426286000 | T10: 3.1047852 | U10: Safe | W10: 1 | X10: =IF(ISBLANK(L10),"n/a",Assumptions!$C$5-L10) | Y10: =IF(ISBLANK(L10),"no data",IF(L10>Assumptions!$C$5,"BREACH","Compliant"))
A11: KSS | B11: KOHLS Corp | C11: 46144 | D11: BBB | E11: Medium | F11: Clear | G11: 15461000000 | H11: 1309000000 | I11: 0.03945411 | J11: 1387000000 | K11: 958000000 | L11: 1.0595875 | M11: 0.73185638 | N11: 4.76 | O11: 1052000000 | P11: 0.75847152 | Q11: 1.4815416 | R11: 0.30628803 | S11: 1187000000 | T11: 1.6609809 | U11: Grey | W11: 1 | X11: =IF(ISBLANK(L11),"n/a",Assumptions!$C$5-L11) | Y11: =IF(ISBLANK(L11),"no data",IF(L11>Assumptions!$C$5,"BREACH","Compliant"))
A12: GAP | B12: GAP INC | C12: 46144 | D12: AA | E12: Low | F12: Clear | G12: 15400000000 | H12: 1803000000 | I12: 0.084415584 | J12: 1492000000 | K12: -1069000000 | L12: 0.82750971 | M12: -0.59290072 | N12: 19.597826 | O12: 1124000000 | P12: 0.75335121 | Q12: 1.805929 | R12: 1.0837642 | S12: 2338000000 | T12: 3.403418 | U12: Safe | W12: 1 | X12: =IF(ISBLANK(L12),"n/a",Assumptions!$C$5-L12) | Y12: =IF(ISBLANK(L12),"no data",IF(L12>Assumptions!$C$5,"BREACH","Compliant"))
A13: BBY | B13: BEST BUY CO INC | C13: 46144 | D13: A | E13: Low | F13: Clear | G13: 41860000000 | H13: 2354000000 | I13: 0.036789298 | J13: 1169000000 | K13: -580000000 | L13: 0.49660153 | M13: -0.24638912 | N13: 51.173913 | O13: 1605000000 | P13: 1.3729683 | Q13: 1.120944 | R13: 0.4029755 | S13: 943000000 | T13: 1.9707403 | U13: Grey | W13: 1 | X13: =IF(ISBLANK(L13),"n/a",Assumptions!$C$5-L13) | Y13: =IF(ISBLANK(L13),"no data",IF(L13>Assumptions!$C$5,"BREACH","Compliant"))
A14: TJX | B14: TJX COMPANIES INC /DE/ | C14: 46144 | D14: A | E14: Low | F14: Medium | G14: 61584000000 | H14: 8835000000 | I14: 0.1225643 | J14: 2870000000 | K14: -2710000000 | L14: 0.32484437 | M14: -0.30673458 | O14: 5477000000 | P14: 1.9083624 | Q14: 1.1388565 | R14: 0.54181252 | S14: 1785000000 | T14: 3.0225219 | U14: Safe | V14: 0.3471017 | W14: 1 | X14: =IF(ISBLANK(L14),"n/a",Assumptions!$C$5-L14) | Y14: =IF(ISBLANK(L14),"no data",IF(L14>Assumptions!$C$5,"BREACH","Compliant"))
A15: ROST | B15: ROSS STORES, INC. | C15: 46144 | D15: AA | E15: Low | F15: Clear | G15: 23776064000 | H15: 3430965000 | I15: 0.12217804 | J15: 1018187000 | K15: -3112793000 | L15: 0.29676403 | M15: -0.90726457 | O15: 2632326000 | P15: 2.585307 | Q15: 1.5409242 | R15: 0.93521803 | S15: 2658564000 | T15: 4.1233192 | U15: Safe | W15: 1 | X15: =IF(ISBLANK(L15),"n/a",Assumptions!$C$5-L15) | Y15: =IF(ISBLANK(L15),"no data",IF(L15>Assumptions!$C$5,"BREACH","Compliant"))
A16: ANF | B16: ABERCROMBIE & FITCH CO /DE/ | C16: 46144 | D16: AA | E16: Low | F16: Clear | G16: 5282802000 | H16: 845156000 | I16: 0.12993237 | J16: 0 | K16: -594080000 | L16: 0 | M16: -0.70292348 | O16: 416047000 | Q16: 1.448299 | R16: 0.9031335 | S16: 438041000 | T16: 6.3924531 | U16: Safe | W16: 1 | X16: =IF(ISBLANK(L16),"n/a",Assumptions!$C$5-L16) | Y16: =IF(ISBLANK(L16),"no data",IF(L16>Assumptions!$C$5,"BREACH","Compliant"))
A18: Watchlist triggers by name (Level = breach today, Trend = deteriorating, Stress = breaches under scenario):
A19: W: Debt/EBITDA 5.68x above assumed 4.5x covenant | Current ratio 0.74x below 1.0x | Altman Z" -6.70 in distress zone (below 1.1) | Working capital down 44.0% YoY (trigger 20%) | Coverage falls to 0.72x under EBITDA margin -300bps | Coverage falls to 0.52x under Combined recession
A20: BBWI: Operating margin down 169bps YoY (trigger 150bps)
A21: TGT: Current ratio 0.93x below 1.0x
A22: DKS: Operating margin down 495bps YoY (trigger 150bps) | Interest coverage down 33.7% YoY (trigger 25%)
A23: TJX: 35% of debt matures within 12 months - refinancing concentration (trigger 25%)

Sheet Company Detail
A1: Company Underwriting Detail
A2: One page per name: current position, eight-quarter trend, stress results and the triggers driving the recommendation.
A4: GAP - GAP INC | D4: Strongest credit in the portfolio
A5: Recommendation: | B5: APPROVE - within all stated credit policy thresholds
A6: Internal grade: | B6: AA (PD proxy band: Low; scorecard 0.00 on a 0=best / 2=worst scale)
A8: Metric | B8: Actual | C8: Policy threshold
A9: Revenue TTM | B9: 15400000000 | C9: -
A10: EBITDA TTM | B10: 1803000000 | C10: -
A11: Operating margin | B11: 0.084415584 | C11: -
A12: Total debt | B12: 1492000000 | C12: -
A13: Debt/EBITDA | B13: 0.82750971 | C13: <= 4.5x
A14: Net debt/EBITDA | B14: -0.59290072 | C14: -
A15: EBITDA/interest | B15: 19.597826 | C15: >= 2.0x
A16: FCF/debt | B16: 0.75335121 | C16: >= 5%
A17: Current ratio | B17: 1.805929 | C17: >= 1.0x
A18: Quick ratio | B18: 1.0837642 | C18: -
A19: Altman Z" | B19: 3.403418 | C19: >= 1.1
A21: Eight-quarter trend
A22: Metric | B22: 2024-08-03 | C22: 2024-11-02 | D22: 2025-02-01 | E22: 2025-05-03 | F22: 2025-08-02 | G22: 2025-11-01 | H22: 2026-01-31 | I22: 2026-05-02
A23: altman_z_double_prime | B23: 2.5758594 | C23: 2.7760606 | D23: 2.9345287 | E23: 3.1464131 | F23: 3.1286625 | G23: 3.2352193 | H23: 3.262576 | I23: 3.403418
A24: current_ratio | B24: 1.4916253 | C24: 1.5428571 | D24: 1.597973 | E24: 1.7112824 | F24: 1.6818893 | G24: 1.7200366 | H24: 1.7506061 | I24: 1.805929
A25: debt_to_ebitda | B25: 1.0170765 | C25: 0.95083014 | D25: 0.92431762 | E25: 0.89543269 | F25: 0.89711191 | G25: 0.90803898 | H25: 0.92613284 | I25: 0.82750971
A26: ebitda_ttm | B26: 1464000000 | C26: 1566000000 | D26: 1612000000 | E26: 1664000000 | F26: 1662000000 | G26: 1642000000 | H26: 1611000000 | I26: 1803000000
A27: fcf_ttm | B27: 1180000000 | C27: 1108000000 | D27: 1039000000 | E27: 879000000 | F27: 769000000 | G27: 779000000 | H27: 823000000 | I27: 1124000000
A28: interest_coverage | B28: 15.092784 | C28: 17.021739 | D28: 18.528736 | E28: 18.696629 | F28: 18.886364 | G28: 18.659091 | H28: 17.322581 | I28: 19.597826
A29: operating_margin | B29: 0.063402096 | C29: 0.070036101 | D29: 0.073710725 | E29: 0.076973814 | F29: 0.0768825 | G29: 0.074939459 | H29: 0.072562801 | I29: 0.084415584
A30: quick_ratio | B30: 0.83808933 | C30: 0.84180451 | D30: 0.96314496 | E30: 0.97652418 | F30: 0.96434157 | G30: 0.97011284 | H30: 1.0818182 | I30: 1.0837642
A31: working_capital | B31: 1585000000 | C31: 1805000000 | D31: 1947000000 | E31: 2030000000 | F31: 2180000000 | G31: 2361000000 | H31: 2477000000 | I31: 2338000000
A33: Stress scenarios
A34: Scenario | B34: Stressed EBITDA | C34: Debt/EBITDA | D34: EBITDA/interest | E34: FCF/debt | F34: Quick ratio
A35: Baseline (as reported) | B35: 1803000000 | C35: 0.82750971 | D35: 19.597826 | E35: 0.75335121 | F35: 1.0837642
A36: Revenue -10% | B36: 1622700000 | C36: 0.91945523 | D36: 17.638043 | E36: 0.6808445 | F36: 1.0837642
A37: Revenue -20% | B37: 1442400000 | C37: 1.0343871 | D37: 15.678261 | E37: 0.6083378 | F37: 1.0837642
A38: EBITDA margin -300bps | B38: 1341000000 | C38: 1.1126025 | D38: 14.576087 | E38: 0.56756032 | F38: 1.0837642
A39: Rates +200bps | B39: 1803000000 | C39: 0.82750971 | D39: 16.863075 | E39: 0.74585121 | F39: 1.0837642
A40: Inventory +30% (cash funded) | B40: 1803000000 | C40: 0.82750971 | D40: 19.597826 | E40: 0.33210456 | F40: 0.86711479
A41: Combined recession | B41: 1139850000 | C41: 1.3089442 | D41: 10.660774 | E41: 0.057922252 | F41: 0.86711479
A43: Triggers
A44: - nan
A47: TGT - TARGET CORP | D47: Borderline / on watchlist
...

Sheet Stress Scenarios
A1: Stress Scenario Matrix
A2: Assumed covenant 4.5x Debt/EBITDA and 2.0x minimum EBITDA/interest. Red = breach.
A4: Stressed Debt/EBITDA
A5: Ticker | B5: Baseline (as reported) | C5: Revenue -10% | D5: Revenue -20% | E5: EBITDA margin -300bps | F5: Rates +200bps | G5: Inventory +30% (cash funded) | H5: Combined recession
A6: ANF | B6: 0 | C6: 0 | D6: 0 | E6: 0 | F6: 0 | G6: 0 | H6: 0
A7: BBWI | B7: 2.582559 | C7: 2.86951 | D7: 3.2281987 | E7: 3.057589 | F7: 2.582559 | G7: 2.582559 | H7: 3.5971635
A8: BBY | B8: 0.49660153 | C8: 0.55177948 | D8: 0.62075191 | E8: 1.0644691 | F8: 0.49660153 | G8: 0.49660153 | H8: 1.2523166
A9: BURL | B9: 1.4635186 | C9: 1.6261317 | D9: 1.8293982 | E9: 2.0118184 | F9: 1.4635186 | G9: 1.4635186 | H9: 2.3668452
A10: DKS | B10: 1.1048033 | C10: 1.2275592 | D10: 1.3810041 | E10: 1.6588509 | F10: 1.1048033 | G10: 1.1048033 | H10: 1.9515893
A11: GAP | B11: 0.82750971 | C11: 0.91945523 | D11: 1.0343871 | E11: 1.1126025 | F11: 0.82750971 | G11: 0.82750971 | H11: 1.3089442
A12: KSS | B12: 1.0595875 | C12: 1.1773194 | D12: 1.3244843 | E12: 1.64109 | F12: 1.0595875 | G12: 1.0595875 | H12: 1.9306941
A13: M | B13: 1.258148 | C13: 1.3979422 | D13: 1.5726849 | E13: 1.9035394 | F13: 1.258148 | G13: 1.258148 | H13: 2.2394581
A14: ROST | B14: 0.29676403 | C14: 0.32973781 | D14: 0.37095504 | E14: 0.37465259 | F14: 0.29676403 | G14: 0.29676403 | H14: 0.44076775
A15: TGT | B15: 1.9414358 | C15: 2.1571509 | D15: 2.4267947 | E15: 3.2461584 | F15: 1.9414358 | G15: 1.9414358 | H15: 3.8190099
A16: TJX | B16: 0.32484437 | C16: 0.36093819 | D16: 0.40605546 | E16: 0.41073463 | F16: 0.32484437 | G16: 0.32484437 | H16: 0.48321721
A17: W | B17: 5.6849593 | C17: 6.3166215 | D17: 7.1061992 | E17: 26.668574 | F17: 5.6849593 | G17: 5.6849593 | H17: 31.374792
A19: Stressed EBITDA/interest coverage
A20: Ticker | B20: Baseline (as reported) | C20: Revenue -10% | D20: Revenue -20% | E20: EBITDA margin -300bps | F20: Rates +200bps | G20: Inventory +30% (cash funded) | H20: Combined recession
A21: BBWI | B21: 5.1245421 | C21: 4.6120879 | D21: 4.0996337 | E21: 4.3283883 | F21: 4.5256041 | G21: 5.1245421 | H21: 3.2491266
A22: BBY | B22: 51.173913 | C22: 46.056522 | D22: 40.93913 | E22: 23.873913 | F22: 40.804299 | G22: 51.173913 | H22: 16.180794
A23: BURL | B23: 18.265413 | C23: 16.438872 | D23: 14.61233 | E23: 13.287368 | F23: 14.412655 | G23: 18.265413 | H23: 8.9119425
A24: DKS | B24: 24.761674 | C24: 22.285506 | D24: 19.809339 | E24: 16.491403 | F24: 19.442761 | G24: 24.761674 | H24: 11.006632
A25: GAP | B25: 19.597826 | C25: 17.638043 | D25: 15.678261 | E25: 14.576087 | F25: 16.863075 | G25: 19.597826 | H25: 10.660774
A26: KSS | B26: 4.76 | C26: 4.284 | D26: 3.808 | E26: 3.0733455 | F26: 4.5314501 | G26: 4.76 | H26: 2.4869128
A27: M | B27: 20.347368 | C27: 18.312632 | D27: 16.277895 | E27: 13.448632 | F27: 16.200134 | G27: 20.347368 | H27: 9.1013828
A28: ROST | F28: 336.96806 | H28: 226.87685
A29: TGT | B29: 17.762864 | C29: 15.986577 | D29: 14.210291 | E29: 10.623468 | F29: 13.208018 | G29: 17.762864 | H29: 6.7144415
A30: TJX | F30: 307.83972 | H30: 206.94627
A31: W | B31: 3.3931034 | C31: 3.0537931 | D31: 2.7144828 | E31: 0.72331034 | F31: 2.8444239 | G31: 3.3931034 | H31: 0.51539573
A33: Stressed FCF/debt
A34: Ticker | B34: Baseline (as reported) | C34: Revenue -10% | D34: Revenue -20% | E34: EBITDA margin -300bps | F34: Rates +200bps | G34: Inventory +30% (cash funded) | H34: Combined recession
A35: BBWI | B35: 0.25159148 | C35: 0.2283587 | D35: 0.20512593 | E35: 0.21549682 | F35: 0.24409148 | G35: 0.18665929 | H35: 0.11362967
A36: BBY | B36: 1.3729683 | C36: 1.2521471 | D36: 1.1313259 | E36: 0.72841745 | F36: 1.3654683 | G36: -0.06364414 | H36: -0.80024423
A37: BURL | B37: 0.19972222 | C37: 0.15872513 | D37: 0.11772805 | E37: 0.087988995 | F37: 0.19222222 | G37: -0.026245161 | H37: -0.19021404
A38: DKS | B38: 0.21125873 | C38: 0.15695042 | D38: 0.10264211 | E38: 0.029871789 | F38: 0.20375873 | G38: -0.64183287 | H38: -0.88497423
A39: GAP | B39: 0.75335121 | C39: 0.6808445 | D39: 0.6083378 | E39: 0.56756032 | F39: 0.74585121 | G39: 0.33210456 | H39: 0.057922252
A40: KSS | B40: 0.75847152 | C40: 0.70184571 | D40: 0.6452199 | E40: 0.55782408 | F40: 0.75097152 | G40: 0.13186734 | H40: -0.1311217
A41: M | B41: 0.5859375 | C41: 0.53824836 | D41: 0.49055921 | E41: 0.42424836 | F41: 0.5784375 | G41: -0.010238487 | H41: -0.22670798
A42: ROST | B42: 2.585307 | C42: 2.3831262 | D42: 2.1809453 | E42: 2.1649823 | F42: 2.577807 | G42: 1.7081721 | H42: 1.0401248
A43: TGT | B43: 0.19662666 | C43: 0.1657217 | D43: 0.13481674 | E43: 0.072410898 | F43: 0.18912666 | G43: -0.043081414 | H43: -0.20252226
...

Sheet Assumptions
A1: Assumptions & Model Limitations
A2: Nothing in this model is a real negotiated covenant. Every threshold below is an explicit assumption and is the only place it is defined.
A4: Category | B4: Assumption | C4: Value | D4: Rationale
A5: Credit policy | B5: Max Debt/EBITDA (assumed covenant) | C5: 4.5 | D5: Illustrative of total-leverage maintenance tests in public retail term loans. Real agreements are private; this is not one of them.
A6: Credit policy | B6: Min EBITDA/interest coverage | C6: 2 | D6: Typical minimum coverage test.
A7: Credit policy | B7: Min current ratio | C7: 1 | D7: Working-capital liquidity floor.
A8: Credit policy | B8: Min FCF/debt | C8: 0.05 | D8: Below this, the company cannot meaningfully deleverage from cash flow.
A9: Credit policy | B9: Refinancing concentration trigger | C9: 0.25 | D9: Share of total debt maturing within 12 months that warrants a flag.
A10: Altman | B10: Z" distress threshold | C10: 1.1 | D10: Z" (non-manufacturer revision) is used, not the 1968 manufacturing Z.
A11: Altman | B11: Z" safe threshold | C11: 2.6 | D11: Above this = safe zone.
A12: Stress | B12: Floating-rate share of debt | C12: 0.5 | D12: Filings rarely give a clean fixed/floating split; assumed, and only this share reprices in the rate scenario.
A13: Stress | B13: Inventory build | C13: 0.3 | D13: Assumed cash-funded, so current assets are unchanged and the quick ratio absorbs the hit.
A14: Stress | B14: EBITDA-to-FCF passthrough | C14: 0.8 | D14: A sales decline releases working capital, cushioning cash flow, so less than 100% of an EBITDA fall reaches FCF in year one.
A15: Stress | B15: Cash tax rate | C15: 0.25 | D15: Converts the pre-tax earnings shock into an after-tax cash-flow shock.
A16: Early warning | B16: Leverage rise (turns YoY) | C16: 0.75 | D16: Trend trigger: still compliant, but moving the wrong way.
... A19: Scorecard | B19: Min data coverage for a grade | C19: 0.6 | D19: Below this share of scorecard weight the grade is suppressed as NR, so a thin data set cannot produce a flattering grade.
A21: Scorecard weights
A22: Metric | B22: Direction | C22: Good / weak band | D22: Weight
A23: debt_to_ebitda | B23: lower better | C23: 2.0 / 4.0 | D23: 0.25
A24: net_debt_to_ebitda | B24: lower better | C24: 1.5 / 3.5 | D24: 0.1
A25: interest_coverage | B25: higher better | C25: 6.0 / 3.0 | D25: 0.2
A26: fcf_to_debt | B26: higher better | C26: 0.2 / 0.08 | D26: 0.15
A27: current_ratio | B27: higher better | C27: 1.5 / 1.0 | D27: 0.1
A28: quick_ratio | B28: higher better | C28: 0.8 / 0.4 | D28: 0.05
A29: altman_z_double_prime | B29: higher better | C29: 2.6 / 1.1 | D29: 0.15
A31: Known limitations
A32: - Altman Z" was calibrated on non-manufacturers but not on modern e-commerce or omni-channel retail; treat the zone as a ranking, not a verdict.
A33: - The PD proxy is a rules-based scorecard. It was NOT fit to historical default data, so its Low/Medium/High bands are relative risk ranking, not probabilities.
A34: - Covenant thresholds are assumptions. Real agreements often use net leverage, adjusted EBITDA with addbacks, and step-downs, all of which would change headroom.
A35: - Operating lease liabilities are excluded from total debt. Rating agencies often capitalise them, which would raise leverage materially for retailers.
A36: - EBITDA is unadjusted: no addbacks for impairments, restructuring or stock compensation, so it is more conservative than a credit agreement's definition.
A37: - Where a company discloses only net interest quarterly, coverage is computed on a net basis and flagged in the interest_basis column.
A38: - The model uses the latest filed quarter, which lags the market by up to a quarter; it cannot see events since the last filing.

Sheet Data Quality
A1: Extraction Audit
A2: Which XBRL concept fed each metric, how much history it covers, and how much had to be reconstructed from year-to-date disclosures.
A4: Input provenance by company
A5: Ticker | B5: Debt source | C5: EBIT source | D5: Interest basis | E5: Scorecard coverage | F5: Balance sheet as of
A6: W | B6: current + noncurrent legs | C6: reported | D6: net of interest income | E6: 1 | F6: 2026-06-30
A7: BBWI | B7: current + noncurrent legs | C7: reported | D7: gross | E7: 1 | F7: 2026-05-02
A8: TGT | B8: current + noncurrent legs | C8: reported | D8: gross | E8: 1 | F8: 2026-05-02
A9: BURL | B9: current + noncurrent legs | C9: derived: pretax less net interest | D9: gross | E9: 1 | F9: 2026-05-02
A10: M | B10: current + noncurrent legs | C10: reported | D10: net of interest income | E10: 1 | F10: 2026-05-02
A11: DKS | B11: combined debt tag | C11: reported | D11: gross | E11: 1 | F11: 2026-05-02
A12: KSS | B12: current + noncurrent legs | C12: reported | D12: net of interest income | E12: 1 | F12: 2026-05-02
A13: GAP | B13: current + noncurrent legs | C13: reported | D13: gross | E13: 1 | F13: 2026-05-02
A14: BBY | B14: current + noncurrent legs | C14: reported | D14: gross | E14: 1 | F14: 2026-05-02
A15: TJX | B15: current + noncurrent legs | C15: derived: pretax less net interest | D15: net of interest income | E15: 1 | F15: 2026-05-02
A16: ROST | B16: current + noncurrent legs | C16: reported | D16: net of interest income | E16: 1 | F16: 2026-05-02
A17: ANF | B17: nil (debt caption removed after full repayment) | C17: reported | D17: net of interest income | E17: 1 | F17: 2026-05-02
A19: Concept-level extraction log
A20: Ticker | B20: Metric | C20: Concept(s) used | D20: Quarters | E20: First period | F20: Last period | G20: Share de-cumulated
A21: ANF | B21: capex | C21: PaymentsToAcquirePropertyPlantAndEquipment | D21: 67 | E21: 2009-10-31 | F21: 2026-05-02 | G21: 0.746
A22: ANF | B22: cash | C22: CashAndCashEquivalentsAtCarryingValue | D22: 71 | E22: 2008-02-02 | F22: 2026-05-02 | G22: 0
A23: ANF | B23: current_assets | C23: AssetsCurrent | D23: 66 | E23: 2010-01-30 | F23: 2026-05-02 | G23: 0
A24: ANF | B24: current_liabilities | C24: LiabilitiesCurrent | D24: 66 | E24: 2010-01-30 | F24: 2026-05-02 | G24: 0
A25: ANF | B25: debt_current | C25: LongTermDebtCurrent | D25: 9 | E25: 2013-02-02 | F25: 2020-05-02 | G25: 0
A26: ANF | B26: debt_noncurrent | C26: LongTermDebtNoncurrent | D26: 59 | E26: 2010-01-30 | F26: 2025-02-01 | G26: 0
A27: ANF | B27: debt_total_reported | C27: DebtLongtermAndShorttermCombinedAmount,LongTermDebt | D27: 9 | E27: 2013-02-02 | F27: 2018-11-03 | G27: 0
A28: ANF | B28: depreciation_amortization | C28: DepreciationAndAmortization | D28: 67 | E28: 2009-10-31 | F28: 2026-05-02 | G28: 0.687
A29: ANF | B29: finance_lease_current | D29: 0
A30: ANF | B30: finance_lease_noncurrent | D30: 0
A31: ANF | B31: interest_expense | C31: InterestExpense,FinancingInterestExpense | D31: 22 | E31: 2010-07-31 | F31: 2024-08-03 | G31: 0.227
A32: ANF | B32: interest_income | D32: 0
A33: ANF | B33: inventory | C33: InventoryNet | D33: 66 | E33: 2010-01-30 | F33: 2026-05-02 | G33: 0
A34: ANF | B34: net_interest_income | C34: InterestIncomeExpenseNet | D34: 68 | E34: 2009-08-01 | F34: 2026-05-02 | G34: 0.25
A35: ANF | B35: operating_cash_flow | C35: NetCashProvidedByUsedInOperatingActivities | D35: 67 | E35: 2009-10-31 | F35: 2026-05-02 | G35: 0.746
A36: ANF | B36: operating_income | C36: OperatingIncomeLoss | D36: 68 | E36: 2009-08-01 | F36: 2026-05-02 | G36: 0.25
A37: ANF | B37: operating_lease_liability | C37: OperatingLeaseLiabilityNoncurrent | D37: 31 | E37: 2019-02-02 | F37: 2026-05-02 | G37: 0
A38: ANF | B38: pretax_income | C38: IncomeLossFromContinuingOperationsBeforeIncomeTaxesExtraordinaryItemsNoncontrollingInterest,IncomeLossFromContinuingOperationsBeforeIncomeTaxesMinorityInterestAndIncomeLossFromEquityMethodInvestments | D38: 68 | E38: 2009-08-01 | F38: 2026-05-02 | G38: 0.25
A39: ANF | B39: retained_earnings | C39: RetainedEarningsAccumulatedDeficit | D39: 66 | E39: 2010-01-30 | F39: 2026-05-02 | G39: 0
A40: ANF | B40: revenue | C40: Revenues,SalesRevenueNet | D40: 68 | E40: 2009-08-01 | F40: 2026-05-02 | G40: 0.103
A41: ANF | B41: short_term_borrowings | C41: ShortTermBorrowings | D41: 24 | E41: 2012-01-28 | F41: 2020-05-02 | G41: 0
A42: ANF | B42: short_term_investments | D42: 0
...
